[2023-06-05T08:33:35.966+0000] {processor.py:153} INFO - Started process (PID=37) to work on /opt/airflow/dags/postgres.py
[2023-06-05T08:33:35.968+0000] {processor.py:743} INFO - Processing file /opt/airflow/dags/postgres.py for tasks to queue
[2023-06-05T08:33:35.970+0000] {logging_mixin.py:137} INFO - [2023-06-05T08:33:35.970+0000] {dagbag.py:538} INFO - Filling up the DagBag from /opt/airflow/dags/postgres.py
[2023-06-05T08:33:36.060+0000] {logging_mixin.py:137} INFO - [2023-06-05T08:33:36.050+0000] {dagbag.py:440} ERROR - Failed to bag_dag: /opt/airflow/dags/postgres.py
Traceback (most recent call last):
  File "/home/airflow/.local/lib/python3.7/site-packages/airflow/timetables/_cron.py", line 88, in validate
    croniter(self._expression)
  File "/home/airflow/.local/lib/python3.7/site-packages/croniter/croniter.py", line 166, in __init__
    self.expanded, self.nth_weekday_of_month = self.expand(expr_format, hash_id=hash_id)
  File "/home/airflow/.local/lib/python3.7/site-packages/croniter/croniter.py", line 778, in expand
    return cls._expand(expr_format, hash_id=hash_id)
  File "/home/airflow/.local/lib/python3.7/site-packages/croniter/croniter.py", line 744, in _expand
    expr_format))
croniter.croniter.CroniterBadCronError: [0 0 0 0 0] is not acceptable, out of range

During handling of the above exception, another exception occurred:

Traceback (most recent call last):
  File "/home/airflow/.local/lib/python3.7/site-packages/airflow/models/dagbag.py", line 437, in _process_modules
    dag.validate()
  File "/home/airflow/.local/lib/python3.7/site-packages/airflow/models/dag.py", line 668, in validate
    self.timetable.validate()
  File "/home/airflow/.local/lib/python3.7/site-packages/airflow/timetables/_cron.py", line 90, in validate
    raise AirflowTimetableInvalid(str(e))
airflow.exceptions.AirflowTimetableInvalid: [0 0 0 0 0] is not acceptable, out of range
[2023-06-05T08:33:36.061+0000] {processor.py:755} WARNING - No viable dags retrieved from /opt/airflow/dags/postgres.py
[2023-06-05T08:33:36.098+0000] {processor.py:175} INFO - Processing /opt/airflow/dags/postgres.py took 0.138 seconds
[2023-06-05T08:34:06.594+0000] {processor.py:153} INFO - Started process (PID=80) to work on /opt/airflow/dags/postgres.py
[2023-06-05T08:34:06.596+0000] {processor.py:743} INFO - Processing file /opt/airflow/dags/postgres.py for tasks to queue
[2023-06-05T08:34:06.599+0000] {logging_mixin.py:137} INFO - [2023-06-05T08:34:06.598+0000] {dagbag.py:538} INFO - Filling up the DagBag from /opt/airflow/dags/postgres.py
[2023-06-05T08:34:06.687+0000] {logging_mixin.py:137} INFO - [2023-06-05T08:34:06.682+0000] {dagbag.py:440} ERROR - Failed to bag_dag: /opt/airflow/dags/postgres.py
Traceback (most recent call last):
  File "/home/airflow/.local/lib/python3.7/site-packages/airflow/timetables/_cron.py", line 88, in validate
    croniter(self._expression)
  File "/home/airflow/.local/lib/python3.7/site-packages/croniter/croniter.py", line 166, in __init__
    self.expanded, self.nth_weekday_of_month = self.expand(expr_format, hash_id=hash_id)
  File "/home/airflow/.local/lib/python3.7/site-packages/croniter/croniter.py", line 778, in expand
    return cls._expand(expr_format, hash_id=hash_id)
  File "/home/airflow/.local/lib/python3.7/site-packages/croniter/croniter.py", line 744, in _expand
    expr_format))
croniter.croniter.CroniterBadCronError: [0 0 0 0 0] is not acceptable, out of range

During handling of the above exception, another exception occurred:

Traceback (most recent call last):
  File "/home/airflow/.local/lib/python3.7/site-packages/airflow/models/dagbag.py", line 437, in _process_modules
    dag.validate()
  File "/home/airflow/.local/lib/python3.7/site-packages/airflow/models/dag.py", line 668, in validate
    self.timetable.validate()
  File "/home/airflow/.local/lib/python3.7/site-packages/airflow/timetables/_cron.py", line 90, in validate
    raise AirflowTimetableInvalid(str(e))
airflow.exceptions.AirflowTimetableInvalid: [0 0 0 0 0] is not acceptable, out of range
[2023-06-05T08:34:06.690+0000] {processor.py:755} WARNING - No viable dags retrieved from /opt/airflow/dags/postgres.py
[2023-06-05T08:34:06.750+0000] {processor.py:175} INFO - Processing /opt/airflow/dags/postgres.py took 0.166 seconds
[2023-06-05T08:34:37.417+0000] {processor.py:153} INFO - Started process (PID=106) to work on /opt/airflow/dags/postgres.py
[2023-06-05T08:34:37.419+0000] {processor.py:743} INFO - Processing file /opt/airflow/dags/postgres.py for tasks to queue
[2023-06-05T08:34:37.421+0000] {logging_mixin.py:137} INFO - [2023-06-05T08:34:37.421+0000] {dagbag.py:538} INFO - Filling up the DagBag from /opt/airflow/dags/postgres.py
[2023-06-05T08:34:37.484+0000] {logging_mixin.py:137} INFO - [2023-06-05T08:34:37.480+0000] {dagbag.py:440} ERROR - Failed to bag_dag: /opt/airflow/dags/postgres.py
Traceback (most recent call last):
  File "/home/airflow/.local/lib/python3.7/site-packages/airflow/timetables/_cron.py", line 88, in validate
    croniter(self._expression)
  File "/home/airflow/.local/lib/python3.7/site-packages/croniter/croniter.py", line 166, in __init__
    self.expanded, self.nth_weekday_of_month = self.expand(expr_format, hash_id=hash_id)
  File "/home/airflow/.local/lib/python3.7/site-packages/croniter/croniter.py", line 778, in expand
    return cls._expand(expr_format, hash_id=hash_id)
  File "/home/airflow/.local/lib/python3.7/site-packages/croniter/croniter.py", line 744, in _expand
    expr_format))
croniter.croniter.CroniterBadCronError: [0 0 0 0 0] is not acceptable, out of range

During handling of the above exception, another exception occurred:

Traceback (most recent call last):
  File "/home/airflow/.local/lib/python3.7/site-packages/airflow/models/dagbag.py", line 437, in _process_modules
    dag.validate()
  File "/home/airflow/.local/lib/python3.7/site-packages/airflow/models/dag.py", line 668, in validate
    self.timetable.validate()
  File "/home/airflow/.local/lib/python3.7/site-packages/airflow/timetables/_cron.py", line 90, in validate
    raise AirflowTimetableInvalid(str(e))
airflow.exceptions.AirflowTimetableInvalid: [0 0 0 0 0] is not acceptable, out of range
[2023-06-05T08:34:37.487+0000] {processor.py:755} WARNING - No viable dags retrieved from /opt/airflow/dags/postgres.py
[2023-06-05T08:34:37.519+0000] {processor.py:175} INFO - Processing /opt/airflow/dags/postgres.py took 0.107 seconds
[2023-06-05T08:35:08.081+0000] {processor.py:153} INFO - Started process (PID=149) to work on /opt/airflow/dags/postgres.py
[2023-06-05T08:35:08.088+0000] {processor.py:743} INFO - Processing file /opt/airflow/dags/postgres.py for tasks to queue
[2023-06-05T08:35:08.092+0000] {logging_mixin.py:137} INFO - [2023-06-05T08:35:08.092+0000] {dagbag.py:538} INFO - Filling up the DagBag from /opt/airflow/dags/postgres.py
[2023-06-05T08:35:08.162+0000] {logging_mixin.py:137} INFO - [2023-06-05T08:35:08.160+0000] {dagbag.py:440} ERROR - Failed to bag_dag: /opt/airflow/dags/postgres.py
Traceback (most recent call last):
  File "/home/airflow/.local/lib/python3.7/site-packages/airflow/timetables/_cron.py", line 88, in validate
    croniter(self._expression)
  File "/home/airflow/.local/lib/python3.7/site-packages/croniter/croniter.py", line 166, in __init__
    self.expanded, self.nth_weekday_of_month = self.expand(expr_format, hash_id=hash_id)
  File "/home/airflow/.local/lib/python3.7/site-packages/croniter/croniter.py", line 778, in expand
    return cls._expand(expr_format, hash_id=hash_id)
  File "/home/airflow/.local/lib/python3.7/site-packages/croniter/croniter.py", line 744, in _expand
    expr_format))
croniter.croniter.CroniterBadCronError: [0 0 0 0 0] is not acceptable, out of range

During handling of the above exception, another exception occurred:

Traceback (most recent call last):
  File "/home/airflow/.local/lib/python3.7/site-packages/airflow/models/dagbag.py", line 437, in _process_modules
    dag.validate()
  File "/home/airflow/.local/lib/python3.7/site-packages/airflow/models/dag.py", line 668, in validate
    self.timetable.validate()
  File "/home/airflow/.local/lib/python3.7/site-packages/airflow/timetables/_cron.py", line 90, in validate
    raise AirflowTimetableInvalid(str(e))
airflow.exceptions.AirflowTimetableInvalid: [0 0 0 0 0] is not acceptable, out of range
[2023-06-05T08:35:08.165+0000] {processor.py:755} WARNING - No viable dags retrieved from /opt/airflow/dags/postgres.py
[2023-06-05T08:35:08.204+0000] {processor.py:175} INFO - Processing /opt/airflow/dags/postgres.py took 0.131 seconds
[2023-06-05T08:35:38.974+0000] {processor.py:153} INFO - Started process (PID=188) to work on /opt/airflow/dags/postgres.py
[2023-06-05T08:35:38.978+0000] {processor.py:743} INFO - Processing file /opt/airflow/dags/postgres.py for tasks to queue
[2023-06-05T08:35:38.983+0000] {logging_mixin.py:137} INFO - [2023-06-05T08:35:38.982+0000] {dagbag.py:538} INFO - Filling up the DagBag from /opt/airflow/dags/postgres.py
[2023-06-05T08:35:39.070+0000] {logging_mixin.py:137} INFO - [2023-06-05T08:35:39.064+0000] {dagbag.py:440} ERROR - Failed to bag_dag: /opt/airflow/dags/postgres.py
Traceback (most recent call last):
  File "/home/airflow/.local/lib/python3.7/site-packages/airflow/timetables/_cron.py", line 88, in validate
    croniter(self._expression)
  File "/home/airflow/.local/lib/python3.7/site-packages/croniter/croniter.py", line 166, in __init__
    self.expanded, self.nth_weekday_of_month = self.expand(expr_format, hash_id=hash_id)
  File "/home/airflow/.local/lib/python3.7/site-packages/croniter/croniter.py", line 778, in expand
    return cls._expand(expr_format, hash_id=hash_id)
  File "/home/airflow/.local/lib/python3.7/site-packages/croniter/croniter.py", line 744, in _expand
    expr_format))
croniter.croniter.CroniterBadCronError: [0 0 0 0 0] is not acceptable, out of range

During handling of the above exception, another exception occurred:

Traceback (most recent call last):
  File "/home/airflow/.local/lib/python3.7/site-packages/airflow/models/dagbag.py", line 437, in _process_modules
    dag.validate()
  File "/home/airflow/.local/lib/python3.7/site-packages/airflow/models/dag.py", line 668, in validate
    self.timetable.validate()
  File "/home/airflow/.local/lib/python3.7/site-packages/airflow/timetables/_cron.py", line 90, in validate
    raise AirflowTimetableInvalid(str(e))
airflow.exceptions.AirflowTimetableInvalid: [0 0 0 0 0] is not acceptable, out of range
[2023-06-05T08:35:39.073+0000] {processor.py:755} WARNING - No viable dags retrieved from /opt/airflow/dags/postgres.py
[2023-06-05T08:35:39.125+0000] {processor.py:175} INFO - Processing /opt/airflow/dags/postgres.py took 0.160 seconds
[2023-06-05T08:36:09.779+0000] {processor.py:153} INFO - Started process (PID=224) to work on /opt/airflow/dags/postgres.py
[2023-06-05T08:36:09.781+0000] {processor.py:743} INFO - Processing file /opt/airflow/dags/postgres.py for tasks to queue
[2023-06-05T08:36:09.783+0000] {logging_mixin.py:137} INFO - [2023-06-05T08:36:09.783+0000] {dagbag.py:538} INFO - Filling up the DagBag from /opt/airflow/dags/postgres.py
[2023-06-05T08:36:09.824+0000] {logging_mixin.py:137} INFO - [2023-06-05T08:36:09.822+0000] {dagbag.py:440} ERROR - Failed to bag_dag: /opt/airflow/dags/postgres.py
Traceback (most recent call last):
  File "/home/airflow/.local/lib/python3.7/site-packages/airflow/timetables/_cron.py", line 88, in validate
    croniter(self._expression)
  File "/home/airflow/.local/lib/python3.7/site-packages/croniter/croniter.py", line 166, in __init__
    self.expanded, self.nth_weekday_of_month = self.expand(expr_format, hash_id=hash_id)
  File "/home/airflow/.local/lib/python3.7/site-packages/croniter/croniter.py", line 778, in expand
    return cls._expand(expr_format, hash_id=hash_id)
  File "/home/airflow/.local/lib/python3.7/site-packages/croniter/croniter.py", line 744, in _expand
    expr_format))
croniter.croniter.CroniterBadCronError: [0 0 0 0 0] is not acceptable, out of range

During handling of the above exception, another exception occurred:

Traceback (most recent call last):
  File "/home/airflow/.local/lib/python3.7/site-packages/airflow/models/dagbag.py", line 437, in _process_modules
    dag.validate()
  File "/home/airflow/.local/lib/python3.7/site-packages/airflow/models/dag.py", line 668, in validate
    self.timetable.validate()
  File "/home/airflow/.local/lib/python3.7/site-packages/airflow/timetables/_cron.py", line 90, in validate
    raise AirflowTimetableInvalid(str(e))
airflow.exceptions.AirflowTimetableInvalid: [0 0 0 0 0] is not acceptable, out of range
[2023-06-05T08:36:09.826+0000] {processor.py:755} WARNING - No viable dags retrieved from /opt/airflow/dags/postgres.py
[2023-06-05T08:36:09.853+0000] {processor.py:175} INFO - Processing /opt/airflow/dags/postgres.py took 0.078 seconds
[2023-06-05T08:36:40.559+0000] {processor.py:153} INFO - Started process (PID=271) to work on /opt/airflow/dags/postgres.py
[2023-06-05T08:36:40.562+0000] {processor.py:743} INFO - Processing file /opt/airflow/dags/postgres.py for tasks to queue
[2023-06-05T08:36:40.563+0000] {logging_mixin.py:137} INFO - [2023-06-05T08:36:40.563+0000] {dagbag.py:538} INFO - Filling up the DagBag from /opt/airflow/dags/postgres.py
[2023-06-05T08:36:40.606+0000] {logging_mixin.py:137} INFO - [2023-06-05T08:36:40.604+0000] {dagbag.py:440} ERROR - Failed to bag_dag: /opt/airflow/dags/postgres.py
Traceback (most recent call last):
  File "/home/airflow/.local/lib/python3.7/site-packages/airflow/timetables/_cron.py", line 88, in validate
    croniter(self._expression)
  File "/home/airflow/.local/lib/python3.7/site-packages/croniter/croniter.py", line 166, in __init__
    self.expanded, self.nth_weekday_of_month = self.expand(expr_format, hash_id=hash_id)
  File "/home/airflow/.local/lib/python3.7/site-packages/croniter/croniter.py", line 778, in expand
    return cls._expand(expr_format, hash_id=hash_id)
  File "/home/airflow/.local/lib/python3.7/site-packages/croniter/croniter.py", line 744, in _expand
    expr_format))
croniter.croniter.CroniterBadCronError: [0 0 0 0 0] is not acceptable, out of range

During handling of the above exception, another exception occurred:

Traceback (most recent call last):
  File "/home/airflow/.local/lib/python3.7/site-packages/airflow/models/dagbag.py", line 437, in _process_modules
    dag.validate()
  File "/home/airflow/.local/lib/python3.7/site-packages/airflow/models/dag.py", line 668, in validate
    self.timetable.validate()
  File "/home/airflow/.local/lib/python3.7/site-packages/airflow/timetables/_cron.py", line 90, in validate
    raise AirflowTimetableInvalid(str(e))
airflow.exceptions.AirflowTimetableInvalid: [0 0 0 0 0] is not acceptable, out of range
[2023-06-05T08:36:40.608+0000] {processor.py:755} WARNING - No viable dags retrieved from /opt/airflow/dags/postgres.py
[2023-06-05T08:36:40.633+0000] {processor.py:175} INFO - Processing /opt/airflow/dags/postgres.py took 0.078 seconds
[2023-06-05T08:37:11.257+0000] {processor.py:153} INFO - Started process (PID=305) to work on /opt/airflow/dags/postgres.py
[2023-06-05T08:37:11.259+0000] {processor.py:743} INFO - Processing file /opt/airflow/dags/postgres.py for tasks to queue
[2023-06-05T08:37:11.261+0000] {logging_mixin.py:137} INFO - [2023-06-05T08:37:11.261+0000] {dagbag.py:538} INFO - Filling up the DagBag from /opt/airflow/dags/postgres.py
[2023-06-05T08:37:11.302+0000] {logging_mixin.py:137} INFO - [2023-06-05T08:37:11.301+0000] {dagbag.py:440} ERROR - Failed to bag_dag: /opt/airflow/dags/postgres.py
Traceback (most recent call last):
  File "/home/airflow/.local/lib/python3.7/site-packages/airflow/timetables/_cron.py", line 88, in validate
    croniter(self._expression)
  File "/home/airflow/.local/lib/python3.7/site-packages/croniter/croniter.py", line 166, in __init__
    self.expanded, self.nth_weekday_of_month = self.expand(expr_format, hash_id=hash_id)
  File "/home/airflow/.local/lib/python3.7/site-packages/croniter/croniter.py", line 778, in expand
    return cls._expand(expr_format, hash_id=hash_id)
  File "/home/airflow/.local/lib/python3.7/site-packages/croniter/croniter.py", line 744, in _expand
    expr_format))
croniter.croniter.CroniterBadCronError: [0 0 0 0 0] is not acceptable, out of range

During handling of the above exception, another exception occurred:

Traceback (most recent call last):
  File "/home/airflow/.local/lib/python3.7/site-packages/airflow/models/dagbag.py", line 437, in _process_modules
    dag.validate()
  File "/home/airflow/.local/lib/python3.7/site-packages/airflow/models/dag.py", line 668, in validate
    self.timetable.validate()
  File "/home/airflow/.local/lib/python3.7/site-packages/airflow/timetables/_cron.py", line 90, in validate
    raise AirflowTimetableInvalid(str(e))
airflow.exceptions.AirflowTimetableInvalid: [0 0 0 0 0] is not acceptable, out of range
[2023-06-05T08:37:11.304+0000] {processor.py:755} WARNING - No viable dags retrieved from /opt/airflow/dags/postgres.py
[2023-06-05T08:37:11.325+0000] {processor.py:175} INFO - Processing /opt/airflow/dags/postgres.py took 0.073 seconds
[2023-06-05T08:37:41.936+0000] {processor.py:153} INFO - Started process (PID=346) to work on /opt/airflow/dags/postgres.py
[2023-06-05T08:37:41.940+0000] {processor.py:743} INFO - Processing file /opt/airflow/dags/postgres.py for tasks to queue
[2023-06-05T08:37:41.942+0000] {logging_mixin.py:137} INFO - [2023-06-05T08:37:41.942+0000] {dagbag.py:538} INFO - Filling up the DagBag from /opt/airflow/dags/postgres.py
[2023-06-05T08:37:41.985+0000] {logging_mixin.py:137} INFO - [2023-06-05T08:37:41.983+0000] {dagbag.py:440} ERROR - Failed to bag_dag: /opt/airflow/dags/postgres.py
Traceback (most recent call last):
  File "/home/airflow/.local/lib/python3.7/site-packages/airflow/timetables/_cron.py", line 88, in validate
    croniter(self._expression)
  File "/home/airflow/.local/lib/python3.7/site-packages/croniter/croniter.py", line 166, in __init__
    self.expanded, self.nth_weekday_of_month = self.expand(expr_format, hash_id=hash_id)
  File "/home/airflow/.local/lib/python3.7/site-packages/croniter/croniter.py", line 778, in expand
    return cls._expand(expr_format, hash_id=hash_id)
  File "/home/airflow/.local/lib/python3.7/site-packages/croniter/croniter.py", line 744, in _expand
    expr_format))
croniter.croniter.CroniterBadCronError: [0 0 0 0 0] is not acceptable, out of range

During handling of the above exception, another exception occurred:

Traceback (most recent call last):
  File "/home/airflow/.local/lib/python3.7/site-packages/airflow/models/dagbag.py", line 437, in _process_modules
    dag.validate()
  File "/home/airflow/.local/lib/python3.7/site-packages/airflow/models/dag.py", line 668, in validate
    self.timetable.validate()
  File "/home/airflow/.local/lib/python3.7/site-packages/airflow/timetables/_cron.py", line 90, in validate
    raise AirflowTimetableInvalid(str(e))
airflow.exceptions.AirflowTimetableInvalid: [0 0 0 0 0] is not acceptable, out of range
[2023-06-05T08:37:41.987+0000] {processor.py:755} WARNING - No viable dags retrieved from /opt/airflow/dags/postgres.py
[2023-06-05T08:37:42.014+0000] {processor.py:175} INFO - Processing /opt/airflow/dags/postgres.py took 0.082 seconds
[2023-06-05T08:38:12.638+0000] {processor.py:153} INFO - Started process (PID=388) to work on /opt/airflow/dags/postgres.py
[2023-06-05T08:38:12.640+0000] {processor.py:743} INFO - Processing file /opt/airflow/dags/postgres.py for tasks to queue
[2023-06-05T08:38:12.642+0000] {logging_mixin.py:137} INFO - [2023-06-05T08:38:12.642+0000] {dagbag.py:538} INFO - Filling up the DagBag from /opt/airflow/dags/postgres.py
[2023-06-05T08:38:12.678+0000] {logging_mixin.py:137} INFO - [2023-06-05T08:38:12.677+0000] {dagbag.py:440} ERROR - Failed to bag_dag: /opt/airflow/dags/postgres.py
Traceback (most recent call last):
  File "/home/airflow/.local/lib/python3.7/site-packages/airflow/timetables/_cron.py", line 88, in validate
    croniter(self._expression)
  File "/home/airflow/.local/lib/python3.7/site-packages/croniter/croniter.py", line 166, in __init__
    self.expanded, self.nth_weekday_of_month = self.expand(expr_format, hash_id=hash_id)
  File "/home/airflow/.local/lib/python3.7/site-packages/croniter/croniter.py", line 778, in expand
    return cls._expand(expr_format, hash_id=hash_id)
  File "/home/airflow/.local/lib/python3.7/site-packages/croniter/croniter.py", line 744, in _expand
    expr_format))
croniter.croniter.CroniterBadCronError: [0 0 0 0 0] is not acceptable, out of range

During handling of the above exception, another exception occurred:

Traceback (most recent call last):
  File "/home/airflow/.local/lib/python3.7/site-packages/airflow/models/dagbag.py", line 437, in _process_modules
    dag.validate()
  File "/home/airflow/.local/lib/python3.7/site-packages/airflow/models/dag.py", line 668, in validate
    self.timetable.validate()
  File "/home/airflow/.local/lib/python3.7/site-packages/airflow/timetables/_cron.py", line 90, in validate
    raise AirflowTimetableInvalid(str(e))
airflow.exceptions.AirflowTimetableInvalid: [0 0 0 0 0] is not acceptable, out of range
[2023-06-05T08:38:12.682+0000] {processor.py:755} WARNING - No viable dags retrieved from /opt/airflow/dags/postgres.py
[2023-06-05T08:38:12.703+0000] {processor.py:175} INFO - Processing /opt/airflow/dags/postgres.py took 0.069 seconds
[2023-06-05T08:38:43.376+0000] {processor.py:153} INFO - Started process (PID=423) to work on /opt/airflow/dags/postgres.py
[2023-06-05T08:38:43.378+0000] {processor.py:743} INFO - Processing file /opt/airflow/dags/postgres.py for tasks to queue
[2023-06-05T08:38:43.380+0000] {logging_mixin.py:137} INFO - [2023-06-05T08:38:43.380+0000] {dagbag.py:538} INFO - Filling up the DagBag from /opt/airflow/dags/postgres.py
[2023-06-05T08:38:43.424+0000] {logging_mixin.py:137} INFO - [2023-06-05T08:38:43.422+0000] {dagbag.py:440} ERROR - Failed to bag_dag: /opt/airflow/dags/postgres.py
Traceback (most recent call last):
  File "/home/airflow/.local/lib/python3.7/site-packages/airflow/timetables/_cron.py", line 88, in validate
    croniter(self._expression)
  File "/home/airflow/.local/lib/python3.7/site-packages/croniter/croniter.py", line 166, in __init__
    self.expanded, self.nth_weekday_of_month = self.expand(expr_format, hash_id=hash_id)
  File "/home/airflow/.local/lib/python3.7/site-packages/croniter/croniter.py", line 778, in expand
    return cls._expand(expr_format, hash_id=hash_id)
  File "/home/airflow/.local/lib/python3.7/site-packages/croniter/croniter.py", line 744, in _expand
    expr_format))
croniter.croniter.CroniterBadCronError: [0 0 0 0 0] is not acceptable, out of range

During handling of the above exception, another exception occurred:

Traceback (most recent call last):
  File "/home/airflow/.local/lib/python3.7/site-packages/airflow/models/dagbag.py", line 437, in _process_modules
    dag.validate()
  File "/home/airflow/.local/lib/python3.7/site-packages/airflow/models/dag.py", line 668, in validate
    self.timetable.validate()
  File "/home/airflow/.local/lib/python3.7/site-packages/airflow/timetables/_cron.py", line 90, in validate
    raise AirflowTimetableInvalid(str(e))
airflow.exceptions.AirflowTimetableInvalid: [0 0 0 0 0] is not acceptable, out of range
[2023-06-05T08:38:43.426+0000] {processor.py:755} WARNING - No viable dags retrieved from /opt/airflow/dags/postgres.py
[2023-06-05T08:38:43.454+0000] {processor.py:175} INFO - Processing /opt/airflow/dags/postgres.py took 0.084 seconds
[2023-06-05T08:39:14.062+0000] {processor.py:153} INFO - Started process (PID=471) to work on /opt/airflow/dags/postgres.py
[2023-06-05T08:39:14.065+0000] {processor.py:743} INFO - Processing file /opt/airflow/dags/postgres.py for tasks to queue
[2023-06-05T08:39:14.067+0000] {logging_mixin.py:137} INFO - [2023-06-05T08:39:14.067+0000] {dagbag.py:538} INFO - Filling up the DagBag from /opt/airflow/dags/postgres.py
[2023-06-05T08:39:14.109+0000] {logging_mixin.py:137} INFO - [2023-06-05T08:39:14.107+0000] {dagbag.py:440} ERROR - Failed to bag_dag: /opt/airflow/dags/postgres.py
Traceback (most recent call last):
  File "/home/airflow/.local/lib/python3.7/site-packages/airflow/timetables/_cron.py", line 88, in validate
    croniter(self._expression)
  File "/home/airflow/.local/lib/python3.7/site-packages/croniter/croniter.py", line 166, in __init__
    self.expanded, self.nth_weekday_of_month = self.expand(expr_format, hash_id=hash_id)
  File "/home/airflow/.local/lib/python3.7/site-packages/croniter/croniter.py", line 778, in expand
    return cls._expand(expr_format, hash_id=hash_id)
  File "/home/airflow/.local/lib/python3.7/site-packages/croniter/croniter.py", line 744, in _expand
    expr_format))
croniter.croniter.CroniterBadCronError: [0 0 0 0 0] is not acceptable, out of range

During handling of the above exception, another exception occurred:

Traceback (most recent call last):
  File "/home/airflow/.local/lib/python3.7/site-packages/airflow/models/dagbag.py", line 437, in _process_modules
    dag.validate()
  File "/home/airflow/.local/lib/python3.7/site-packages/airflow/models/dag.py", line 668, in validate
    self.timetable.validate()
  File "/home/airflow/.local/lib/python3.7/site-packages/airflow/timetables/_cron.py", line 90, in validate
    raise AirflowTimetableInvalid(str(e))
airflow.exceptions.AirflowTimetableInvalid: [0 0 0 0 0] is not acceptable, out of range
[2023-06-05T08:39:14.112+0000] {processor.py:755} WARNING - No viable dags retrieved from /opt/airflow/dags/postgres.py
[2023-06-05T08:39:14.140+0000] {processor.py:175} INFO - Processing /opt/airflow/dags/postgres.py took 0.083 seconds
[2023-06-05T08:39:44.614+0000] {processor.py:153} INFO - Started process (PID=505) to work on /opt/airflow/dags/postgres.py
[2023-06-05T08:39:44.617+0000] {processor.py:743} INFO - Processing file /opt/airflow/dags/postgres.py for tasks to queue
[2023-06-05T08:39:44.618+0000] {logging_mixin.py:137} INFO - [2023-06-05T08:39:44.618+0000] {dagbag.py:538} INFO - Filling up the DagBag from /opt/airflow/dags/postgres.py
[2023-06-05T08:39:44.655+0000] {logging_mixin.py:137} INFO - [2023-06-05T08:39:44.653+0000] {dagbag.py:440} ERROR - Failed to bag_dag: /opt/airflow/dags/postgres.py
Traceback (most recent call last):
  File "/home/airflow/.local/lib/python3.7/site-packages/airflow/timetables/_cron.py", line 88, in validate
    croniter(self._expression)
  File "/home/airflow/.local/lib/python3.7/site-packages/croniter/croniter.py", line 166, in __init__
    self.expanded, self.nth_weekday_of_month = self.expand(expr_format, hash_id=hash_id)
  File "/home/airflow/.local/lib/python3.7/site-packages/croniter/croniter.py", line 778, in expand
    return cls._expand(expr_format, hash_id=hash_id)
  File "/home/airflow/.local/lib/python3.7/site-packages/croniter/croniter.py", line 744, in _expand
    expr_format))
croniter.croniter.CroniterBadCronError: [0 0 0 0 0] is not acceptable, out of range

During handling of the above exception, another exception occurred:

Traceback (most recent call last):
  File "/home/airflow/.local/lib/python3.7/site-packages/airflow/models/dagbag.py", line 437, in _process_modules
    dag.validate()
  File "/home/airflow/.local/lib/python3.7/site-packages/airflow/models/dag.py", line 668, in validate
    self.timetable.validate()
  File "/home/airflow/.local/lib/python3.7/site-packages/airflow/timetables/_cron.py", line 90, in validate
    raise AirflowTimetableInvalid(str(e))
airflow.exceptions.AirflowTimetableInvalid: [0 0 0 0 0] is not acceptable, out of range
[2023-06-05T08:39:44.656+0000] {processor.py:755} WARNING - No viable dags retrieved from /opt/airflow/dags/postgres.py
[2023-06-05T08:39:44.677+0000] {processor.py:175} INFO - Processing /opt/airflow/dags/postgres.py took 0.068 seconds
[2023-06-05T08:40:15.336+0000] {processor.py:153} INFO - Started process (PID=546) to work on /opt/airflow/dags/postgres.py
[2023-06-05T08:40:15.339+0000] {processor.py:743} INFO - Processing file /opt/airflow/dags/postgres.py for tasks to queue
[2023-06-05T08:40:15.341+0000] {logging_mixin.py:137} INFO - [2023-06-05T08:40:15.341+0000] {dagbag.py:538} INFO - Filling up the DagBag from /opt/airflow/dags/postgres.py
[2023-06-05T08:40:15.382+0000] {logging_mixin.py:137} INFO - [2023-06-05T08:40:15.380+0000] {dagbag.py:440} ERROR - Failed to bag_dag: /opt/airflow/dags/postgres.py
Traceback (most recent call last):
  File "/home/airflow/.local/lib/python3.7/site-packages/airflow/timetables/_cron.py", line 88, in validate
    croniter(self._expression)
  File "/home/airflow/.local/lib/python3.7/site-packages/croniter/croniter.py", line 166, in __init__
    self.expanded, self.nth_weekday_of_month = self.expand(expr_format, hash_id=hash_id)
  File "/home/airflow/.local/lib/python3.7/site-packages/croniter/croniter.py", line 778, in expand
    return cls._expand(expr_format, hash_id=hash_id)
  File "/home/airflow/.local/lib/python3.7/site-packages/croniter/croniter.py", line 744, in _expand
    expr_format))
croniter.croniter.CroniterBadCronError: [0 0 0 0 0] is not acceptable, out of range

During handling of the above exception, another exception occurred:

Traceback (most recent call last):
  File "/home/airflow/.local/lib/python3.7/site-packages/airflow/models/dagbag.py", line 437, in _process_modules
    dag.validate()
  File "/home/airflow/.local/lib/python3.7/site-packages/airflow/models/dag.py", line 668, in validate
    self.timetable.validate()
  File "/home/airflow/.local/lib/python3.7/site-packages/airflow/timetables/_cron.py", line 90, in validate
    raise AirflowTimetableInvalid(str(e))
airflow.exceptions.AirflowTimetableInvalid: [0 0 0 0 0] is not acceptable, out of range
[2023-06-05T08:40:15.384+0000] {processor.py:755} WARNING - No viable dags retrieved from /opt/airflow/dags/postgres.py
[2023-06-05T08:40:15.411+0000] {processor.py:175} INFO - Processing /opt/airflow/dags/postgres.py took 0.081 seconds
[2023-06-05T08:40:46.073+0000] {processor.py:153} INFO - Started process (PID=587) to work on /opt/airflow/dags/postgres.py
[2023-06-05T08:40:46.076+0000] {processor.py:743} INFO - Processing file /opt/airflow/dags/postgres.py for tasks to queue
[2023-06-05T08:40:46.078+0000] {logging_mixin.py:137} INFO - [2023-06-05T08:40:46.078+0000] {dagbag.py:538} INFO - Filling up the DagBag from /opt/airflow/dags/postgres.py
[2023-06-05T08:40:46.122+0000] {logging_mixin.py:137} INFO - [2023-06-05T08:40:46.120+0000] {dagbag.py:440} ERROR - Failed to bag_dag: /opt/airflow/dags/postgres.py
Traceback (most recent call last):
  File "/home/airflow/.local/lib/python3.7/site-packages/airflow/timetables/_cron.py", line 88, in validate
    croniter(self._expression)
  File "/home/airflow/.local/lib/python3.7/site-packages/croniter/croniter.py", line 166, in __init__
    self.expanded, self.nth_weekday_of_month = self.expand(expr_format, hash_id=hash_id)
  File "/home/airflow/.local/lib/python3.7/site-packages/croniter/croniter.py", line 778, in expand
    return cls._expand(expr_format, hash_id=hash_id)
  File "/home/airflow/.local/lib/python3.7/site-packages/croniter/croniter.py", line 744, in _expand
    expr_format))
croniter.croniter.CroniterBadCronError: [0 0 0 0 0] is not acceptable, out of range

During handling of the above exception, another exception occurred:

Traceback (most recent call last):
  File "/home/airflow/.local/lib/python3.7/site-packages/airflow/models/dagbag.py", line 437, in _process_modules
    dag.validate()
  File "/home/airflow/.local/lib/python3.7/site-packages/airflow/models/dag.py", line 668, in validate
    self.timetable.validate()
  File "/home/airflow/.local/lib/python3.7/site-packages/airflow/timetables/_cron.py", line 90, in validate
    raise AirflowTimetableInvalid(str(e))
airflow.exceptions.AirflowTimetableInvalid: [0 0 0 0 0] is not acceptable, out of range
[2023-06-05T08:40:46.124+0000] {processor.py:755} WARNING - No viable dags retrieved from /opt/airflow/dags/postgres.py
[2023-06-05T08:40:46.151+0000] {processor.py:175} INFO - Processing /opt/airflow/dags/postgres.py took 0.082 seconds
[2023-06-05T08:41:16.600+0000] {processor.py:153} INFO - Started process (PID=621) to work on /opt/airflow/dags/postgres.py
[2023-06-05T08:41:16.603+0000] {processor.py:743} INFO - Processing file /opt/airflow/dags/postgres.py for tasks to queue
[2023-06-05T08:41:16.605+0000] {logging_mixin.py:137} INFO - [2023-06-05T08:41:16.604+0000] {dagbag.py:538} INFO - Filling up the DagBag from /opt/airflow/dags/postgres.py
[2023-06-05T08:41:16.645+0000] {logging_mixin.py:137} INFO - [2023-06-05T08:41:16.643+0000] {dagbag.py:440} ERROR - Failed to bag_dag: /opt/airflow/dags/postgres.py
Traceback (most recent call last):
  File "/home/airflow/.local/lib/python3.7/site-packages/airflow/timetables/_cron.py", line 88, in validate
    croniter(self._expression)
  File "/home/airflow/.local/lib/python3.7/site-packages/croniter/croniter.py", line 166, in __init__
    self.expanded, self.nth_weekday_of_month = self.expand(expr_format, hash_id=hash_id)
  File "/home/airflow/.local/lib/python3.7/site-packages/croniter/croniter.py", line 778, in expand
    return cls._expand(expr_format, hash_id=hash_id)
  File "/home/airflow/.local/lib/python3.7/site-packages/croniter/croniter.py", line 744, in _expand
    expr_format))
croniter.croniter.CroniterBadCronError: [0 0 0 0 0] is not acceptable, out of range

During handling of the above exception, another exception occurred:

Traceback (most recent call last):
  File "/home/airflow/.local/lib/python3.7/site-packages/airflow/models/dagbag.py", line 437, in _process_modules
    dag.validate()
  File "/home/airflow/.local/lib/python3.7/site-packages/airflow/models/dag.py", line 668, in validate
    self.timetable.validate()
  File "/home/airflow/.local/lib/python3.7/site-packages/airflow/timetables/_cron.py", line 90, in validate
    raise AirflowTimetableInvalid(str(e))
airflow.exceptions.AirflowTimetableInvalid: [0 0 0 0 0] is not acceptable, out of range
[2023-06-05T08:41:16.647+0000] {processor.py:755} WARNING - No viable dags retrieved from /opt/airflow/dags/postgres.py
[2023-06-05T08:41:16.672+0000] {processor.py:175} INFO - Processing /opt/airflow/dags/postgres.py took 0.077 seconds
[2023-06-05T08:41:47.228+0000] {processor.py:153} INFO - Started process (PID=669) to work on /opt/airflow/dags/postgres.py
[2023-06-05T08:41:47.231+0000] {processor.py:743} INFO - Processing file /opt/airflow/dags/postgres.py for tasks to queue
[2023-06-05T08:41:47.232+0000] {logging_mixin.py:137} INFO - [2023-06-05T08:41:47.232+0000] {dagbag.py:538} INFO - Filling up the DagBag from /opt/airflow/dags/postgres.py
[2023-06-05T08:41:47.273+0000] {logging_mixin.py:137} INFO - [2023-06-05T08:41:47.271+0000] {dagbag.py:440} ERROR - Failed to bag_dag: /opt/airflow/dags/postgres.py
Traceback (most recent call last):
  File "/home/airflow/.local/lib/python3.7/site-packages/airflow/timetables/_cron.py", line 88, in validate
    croniter(self._expression)
  File "/home/airflow/.local/lib/python3.7/site-packages/croniter/croniter.py", line 166, in __init__
    self.expanded, self.nth_weekday_of_month = self.expand(expr_format, hash_id=hash_id)
  File "/home/airflow/.local/lib/python3.7/site-packages/croniter/croniter.py", line 778, in expand
    return cls._expand(expr_format, hash_id=hash_id)
  File "/home/airflow/.local/lib/python3.7/site-packages/croniter/croniter.py", line 744, in _expand
    expr_format))
croniter.croniter.CroniterBadCronError: [0 0 0 0 0] is not acceptable, out of range

During handling of the above exception, another exception occurred:

Traceback (most recent call last):
  File "/home/airflow/.local/lib/python3.7/site-packages/airflow/models/dagbag.py", line 437, in _process_modules
    dag.validate()
  File "/home/airflow/.local/lib/python3.7/site-packages/airflow/models/dag.py", line 668, in validate
    self.timetable.validate()
  File "/home/airflow/.local/lib/python3.7/site-packages/airflow/timetables/_cron.py", line 90, in validate
    raise AirflowTimetableInvalid(str(e))
airflow.exceptions.AirflowTimetableInvalid: [0 0 0 0 0] is not acceptable, out of range
[2023-06-05T08:41:47.275+0000] {processor.py:755} WARNING - No viable dags retrieved from /opt/airflow/dags/postgres.py
[2023-06-05T08:41:47.299+0000] {processor.py:175} INFO - Processing /opt/airflow/dags/postgres.py took 0.075 seconds
[2023-06-05T08:42:18.126+0000] {processor.py:153} INFO - Started process (PID=703) to work on /opt/airflow/dags/postgres.py
[2023-06-05T08:42:18.130+0000] {processor.py:743} INFO - Processing file /opt/airflow/dags/postgres.py for tasks to queue
[2023-06-05T08:42:18.133+0000] {logging_mixin.py:137} INFO - [2023-06-05T08:42:18.132+0000] {dagbag.py:538} INFO - Filling up the DagBag from /opt/airflow/dags/postgres.py
[2023-06-05T08:42:18.196+0000] {logging_mixin.py:137} INFO - [2023-06-05T08:42:18.193+0000] {dagbag.py:440} ERROR - Failed to bag_dag: /opt/airflow/dags/postgres.py
Traceback (most recent call last):
  File "/home/airflow/.local/lib/python3.7/site-packages/airflow/timetables/_cron.py", line 88, in validate
    croniter(self._expression)
  File "/home/airflow/.local/lib/python3.7/site-packages/croniter/croniter.py", line 166, in __init__
    self.expanded, self.nth_weekday_of_month = self.expand(expr_format, hash_id=hash_id)
  File "/home/airflow/.local/lib/python3.7/site-packages/croniter/croniter.py", line 778, in expand
    return cls._expand(expr_format, hash_id=hash_id)
  File "/home/airflow/.local/lib/python3.7/site-packages/croniter/croniter.py", line 744, in _expand
    expr_format))
croniter.croniter.CroniterBadCronError: [0 0 0 0 0] is not acceptable, out of range

During handling of the above exception, another exception occurred:

Traceback (most recent call last):
  File "/home/airflow/.local/lib/python3.7/site-packages/airflow/models/dagbag.py", line 437, in _process_modules
    dag.validate()
  File "/home/airflow/.local/lib/python3.7/site-packages/airflow/models/dag.py", line 668, in validate
    self.timetable.validate()
  File "/home/airflow/.local/lib/python3.7/site-packages/airflow/timetables/_cron.py", line 90, in validate
    raise AirflowTimetableInvalid(str(e))
airflow.exceptions.AirflowTimetableInvalid: [0 0 0 0 0] is not acceptable, out of range
[2023-06-05T08:42:18.199+0000] {processor.py:755} WARNING - No viable dags retrieved from /opt/airflow/dags/postgres.py
[2023-06-05T08:42:18.238+0000] {processor.py:175} INFO - Processing /opt/airflow/dags/postgres.py took 0.118 seconds
[2023-06-05T08:42:48.925+0000] {processor.py:153} INFO - Started process (PID=751) to work on /opt/airflow/dags/postgres.py
[2023-06-05T08:42:48.928+0000] {processor.py:743} INFO - Processing file /opt/airflow/dags/postgres.py for tasks to queue
[2023-06-05T08:42:48.930+0000] {logging_mixin.py:137} INFO - [2023-06-05T08:42:48.930+0000] {dagbag.py:538} INFO - Filling up the DagBag from /opt/airflow/dags/postgres.py
[2023-06-05T08:42:48.976+0000] {logging_mixin.py:137} INFO - [2023-06-05T08:42:48.974+0000] {dagbag.py:440} ERROR - Failed to bag_dag: /opt/airflow/dags/postgres.py
Traceback (most recent call last):
  File "/home/airflow/.local/lib/python3.7/site-packages/airflow/timetables/_cron.py", line 88, in validate
    croniter(self._expression)
  File "/home/airflow/.local/lib/python3.7/site-packages/croniter/croniter.py", line 166, in __init__
    self.expanded, self.nth_weekday_of_month = self.expand(expr_format, hash_id=hash_id)
  File "/home/airflow/.local/lib/python3.7/site-packages/croniter/croniter.py", line 778, in expand
    return cls._expand(expr_format, hash_id=hash_id)
  File "/home/airflow/.local/lib/python3.7/site-packages/croniter/croniter.py", line 744, in _expand
    expr_format))
croniter.croniter.CroniterBadCronError: [0 0 0 0 0] is not acceptable, out of range

During handling of the above exception, another exception occurred:

Traceback (most recent call last):
  File "/home/airflow/.local/lib/python3.7/site-packages/airflow/models/dagbag.py", line 437, in _process_modules
    dag.validate()
  File "/home/airflow/.local/lib/python3.7/site-packages/airflow/models/dag.py", line 668, in validate
    self.timetable.validate()
  File "/home/airflow/.local/lib/python3.7/site-packages/airflow/timetables/_cron.py", line 90, in validate
    raise AirflowTimetableInvalid(str(e))
airflow.exceptions.AirflowTimetableInvalid: [0 0 0 0 0] is not acceptable, out of range
[2023-06-05T08:42:48.978+0000] {processor.py:755} WARNING - No viable dags retrieved from /opt/airflow/dags/postgres.py
[2023-06-05T08:42:49.011+0000] {processor.py:175} INFO - Processing /opt/airflow/dags/postgres.py took 0.090 seconds
[2023-06-05T08:43:19.438+0000] {processor.py:153} INFO - Started process (PID=785) to work on /opt/airflow/dags/postgres.py
[2023-06-05T08:43:19.441+0000] {processor.py:743} INFO - Processing file /opt/airflow/dags/postgres.py for tasks to queue
[2023-06-05T08:43:19.443+0000] {logging_mixin.py:137} INFO - [2023-06-05T08:43:19.443+0000] {dagbag.py:538} INFO - Filling up the DagBag from /opt/airflow/dags/postgres.py
[2023-06-05T08:43:19.493+0000] {logging_mixin.py:137} INFO - [2023-06-05T08:43:19.489+0000] {dagbag.py:440} ERROR - Failed to bag_dag: /opt/airflow/dags/postgres.py
Traceback (most recent call last):
  File "/home/airflow/.local/lib/python3.7/site-packages/airflow/timetables/_cron.py", line 88, in validate
    croniter(self._expression)
  File "/home/airflow/.local/lib/python3.7/site-packages/croniter/croniter.py", line 166, in __init__
    self.expanded, self.nth_weekday_of_month = self.expand(expr_format, hash_id=hash_id)
  File "/home/airflow/.local/lib/python3.7/site-packages/croniter/croniter.py", line 778, in expand
    return cls._expand(expr_format, hash_id=hash_id)
  File "/home/airflow/.local/lib/python3.7/site-packages/croniter/croniter.py", line 744, in _expand
    expr_format))
croniter.croniter.CroniterBadCronError: [0 0 0 0 0] is not acceptable, out of range

During handling of the above exception, another exception occurred:

Traceback (most recent call last):
  File "/home/airflow/.local/lib/python3.7/site-packages/airflow/models/dagbag.py", line 437, in _process_modules
    dag.validate()
  File "/home/airflow/.local/lib/python3.7/site-packages/airflow/models/dag.py", line 668, in validate
    self.timetable.validate()
  File "/home/airflow/.local/lib/python3.7/site-packages/airflow/timetables/_cron.py", line 90, in validate
    raise AirflowTimetableInvalid(str(e))
airflow.exceptions.AirflowTimetableInvalid: [0 0 0 0 0] is not acceptable, out of range
[2023-06-05T08:43:19.495+0000] {processor.py:755} WARNING - No viable dags retrieved from /opt/airflow/dags/postgres.py
[2023-06-05T08:43:19.527+0000] {processor.py:175} INFO - Processing /opt/airflow/dags/postgres.py took 0.094 seconds
[2023-06-05T08:43:50.121+0000] {processor.py:153} INFO - Started process (PID=829) to work on /opt/airflow/dags/postgres.py
[2023-06-05T08:43:50.124+0000] {processor.py:743} INFO - Processing file /opt/airflow/dags/postgres.py for tasks to queue
[2023-06-05T08:43:50.126+0000] {logging_mixin.py:137} INFO - [2023-06-05T08:43:50.126+0000] {dagbag.py:538} INFO - Filling up the DagBag from /opt/airflow/dags/postgres.py
[2023-06-05T08:43:50.170+0000] {logging_mixin.py:137} INFO - [2023-06-05T08:43:50.167+0000] {dagbag.py:440} ERROR - Failed to bag_dag: /opt/airflow/dags/postgres.py
Traceback (most recent call last):
  File "/home/airflow/.local/lib/python3.7/site-packages/airflow/timetables/_cron.py", line 88, in validate
    croniter(self._expression)
  File "/home/airflow/.local/lib/python3.7/site-packages/croniter/croniter.py", line 166, in __init__
    self.expanded, self.nth_weekday_of_month = self.expand(expr_format, hash_id=hash_id)
  File "/home/airflow/.local/lib/python3.7/site-packages/croniter/croniter.py", line 778, in expand
    return cls._expand(expr_format, hash_id=hash_id)
  File "/home/airflow/.local/lib/python3.7/site-packages/croniter/croniter.py", line 744, in _expand
    expr_format))
croniter.croniter.CroniterBadCronError: [0 0 0 0 0] is not acceptable, out of range

During handling of the above exception, another exception occurred:

Traceback (most recent call last):
  File "/home/airflow/.local/lib/python3.7/site-packages/airflow/models/dagbag.py", line 437, in _process_modules
    dag.validate()
  File "/home/airflow/.local/lib/python3.7/site-packages/airflow/models/dag.py", line 668, in validate
    self.timetable.validate()
  File "/home/airflow/.local/lib/python3.7/site-packages/airflow/timetables/_cron.py", line 90, in validate
    raise AirflowTimetableInvalid(str(e))
airflow.exceptions.AirflowTimetableInvalid: [0 0 0 0 0] is not acceptable, out of range
[2023-06-05T08:43:50.172+0000] {processor.py:755} WARNING - No viable dags retrieved from /opt/airflow/dags/postgres.py
[2023-06-05T08:43:50.199+0000] {processor.py:175} INFO - Processing /opt/airflow/dags/postgres.py took 0.083 seconds
[2023-06-05T08:44:20.829+0000] {processor.py:153} INFO - Started process (PID=869) to work on /opt/airflow/dags/postgres.py
[2023-06-05T08:44:20.831+0000] {processor.py:743} INFO - Processing file /opt/airflow/dags/postgres.py for tasks to queue
[2023-06-05T08:44:20.833+0000] {logging_mixin.py:137} INFO - [2023-06-05T08:44:20.833+0000] {dagbag.py:538} INFO - Filling up the DagBag from /opt/airflow/dags/postgres.py
[2023-06-05T08:44:20.876+0000] {logging_mixin.py:137} INFO - [2023-06-05T08:44:20.874+0000] {dagbag.py:440} ERROR - Failed to bag_dag: /opt/airflow/dags/postgres.py
Traceback (most recent call last):
  File "/home/airflow/.local/lib/python3.7/site-packages/airflow/timetables/_cron.py", line 88, in validate
    croniter(self._expression)
  File "/home/airflow/.local/lib/python3.7/site-packages/croniter/croniter.py", line 166, in __init__
    self.expanded, self.nth_weekday_of_month = self.expand(expr_format, hash_id=hash_id)
  File "/home/airflow/.local/lib/python3.7/site-packages/croniter/croniter.py", line 778, in expand
    return cls._expand(expr_format, hash_id=hash_id)
  File "/home/airflow/.local/lib/python3.7/site-packages/croniter/croniter.py", line 744, in _expand
    expr_format))
croniter.croniter.CroniterBadCronError: [0 0 0 0 0] is not acceptable, out of range

During handling of the above exception, another exception occurred:

Traceback (most recent call last):
  File "/home/airflow/.local/lib/python3.7/site-packages/airflow/models/dagbag.py", line 437, in _process_modules
    dag.validate()
  File "/home/airflow/.local/lib/python3.7/site-packages/airflow/models/dag.py", line 668, in validate
    self.timetable.validate()
  File "/home/airflow/.local/lib/python3.7/site-packages/airflow/timetables/_cron.py", line 90, in validate
    raise AirflowTimetableInvalid(str(e))
airflow.exceptions.AirflowTimetableInvalid: [0 0 0 0 0] is not acceptable, out of range
[2023-06-05T08:44:20.878+0000] {processor.py:755} WARNING - No viable dags retrieved from /opt/airflow/dags/postgres.py
[2023-06-05T08:44:20.906+0000] {processor.py:175} INFO - Processing /opt/airflow/dags/postgres.py took 0.082 seconds
[2023-06-05T08:44:51.340+0000] {processor.py:153} INFO - Started process (PID=913) to work on /opt/airflow/dags/postgres.py
[2023-06-05T08:44:51.342+0000] {processor.py:743} INFO - Processing file /opt/airflow/dags/postgres.py for tasks to queue
[2023-06-05T08:44:51.344+0000] {logging_mixin.py:137} INFO - [2023-06-05T08:44:51.344+0000] {dagbag.py:538} INFO - Filling up the DagBag from /opt/airflow/dags/postgres.py
[2023-06-05T08:44:51.405+0000] {logging_mixin.py:137} INFO - [2023-06-05T08:44:51.401+0000] {dagbag.py:440} ERROR - Failed to bag_dag: /opt/airflow/dags/postgres.py
Traceback (most recent call last):
  File "/home/airflow/.local/lib/python3.7/site-packages/airflow/timetables/_cron.py", line 88, in validate
    croniter(self._expression)
  File "/home/airflow/.local/lib/python3.7/site-packages/croniter/croniter.py", line 166, in __init__
    self.expanded, self.nth_weekday_of_month = self.expand(expr_format, hash_id=hash_id)
  File "/home/airflow/.local/lib/python3.7/site-packages/croniter/croniter.py", line 778, in expand
    return cls._expand(expr_format, hash_id=hash_id)
  File "/home/airflow/.local/lib/python3.7/site-packages/croniter/croniter.py", line 744, in _expand
    expr_format))
croniter.croniter.CroniterBadCronError: [0 0 0 0 0] is not acceptable, out of range

During handling of the above exception, another exception occurred:

Traceback (most recent call last):
  File "/home/airflow/.local/lib/python3.7/site-packages/airflow/models/dagbag.py", line 437, in _process_modules
    dag.validate()
  File "/home/airflow/.local/lib/python3.7/site-packages/airflow/models/dag.py", line 668, in validate
    self.timetable.validate()
  File "/home/airflow/.local/lib/python3.7/site-packages/airflow/timetables/_cron.py", line 90, in validate
    raise AirflowTimetableInvalid(str(e))
airflow.exceptions.AirflowTimetableInvalid: [0 0 0 0 0] is not acceptable, out of range
[2023-06-05T08:44:51.424+0000] {processor.py:755} WARNING - No viable dags retrieved from /opt/airflow/dags/postgres.py
[2023-06-05T08:44:51.481+0000] {processor.py:175} INFO - Processing /opt/airflow/dags/postgres.py took 0.146 seconds
[2023-06-05T08:45:22.102+0000] {processor.py:153} INFO - Started process (PID=953) to work on /opt/airflow/dags/postgres.py
[2023-06-05T08:45:22.104+0000] {processor.py:743} INFO - Processing file /opt/airflow/dags/postgres.py for tasks to queue
[2023-06-05T08:45:22.106+0000] {logging_mixin.py:137} INFO - [2023-06-05T08:45:22.106+0000] {dagbag.py:538} INFO - Filling up the DagBag from /opt/airflow/dags/postgres.py
[2023-06-05T08:45:22.146+0000] {logging_mixin.py:137} INFO - [2023-06-05T08:45:22.144+0000] {dagbag.py:440} ERROR - Failed to bag_dag: /opt/airflow/dags/postgres.py
Traceback (most recent call last):
  File "/home/airflow/.local/lib/python3.7/site-packages/airflow/timetables/_cron.py", line 88, in validate
    croniter(self._expression)
  File "/home/airflow/.local/lib/python3.7/site-packages/croniter/croniter.py", line 166, in __init__
    self.expanded, self.nth_weekday_of_month = self.expand(expr_format, hash_id=hash_id)
  File "/home/airflow/.local/lib/python3.7/site-packages/croniter/croniter.py", line 778, in expand
    return cls._expand(expr_format, hash_id=hash_id)
  File "/home/airflow/.local/lib/python3.7/site-packages/croniter/croniter.py", line 744, in _expand
    expr_format))
croniter.croniter.CroniterBadCronError: [0 0 0 0 0] is not acceptable, out of range

During handling of the above exception, another exception occurred:

Traceback (most recent call last):
  File "/home/airflow/.local/lib/python3.7/site-packages/airflow/models/dagbag.py", line 437, in _process_modules
    dag.validate()
  File "/home/airflow/.local/lib/python3.7/site-packages/airflow/models/dag.py", line 668, in validate
    self.timetable.validate()
  File "/home/airflow/.local/lib/python3.7/site-packages/airflow/timetables/_cron.py", line 90, in validate
    raise AirflowTimetableInvalid(str(e))
airflow.exceptions.AirflowTimetableInvalid: [0 0 0 0 0] is not acceptable, out of range
[2023-06-05T08:45:22.147+0000] {processor.py:755} WARNING - No viable dags retrieved from /opt/airflow/dags/postgres.py
[2023-06-05T08:45:22.169+0000] {processor.py:175} INFO - Processing /opt/airflow/dags/postgres.py took 0.071 seconds
[2023-06-05T08:45:52.746+0000] {processor.py:153} INFO - Started process (PID=988) to work on /opt/airflow/dags/postgres.py
[2023-06-05T08:45:52.749+0000] {processor.py:743} INFO - Processing file /opt/airflow/dags/postgres.py for tasks to queue
[2023-06-05T08:45:52.751+0000] {logging_mixin.py:137} INFO - [2023-06-05T08:45:52.750+0000] {dagbag.py:538} INFO - Filling up the DagBag from /opt/airflow/dags/postgres.py
[2023-06-05T08:45:52.789+0000] {logging_mixin.py:137} INFO - [2023-06-05T08:45:52.787+0000] {dagbag.py:440} ERROR - Failed to bag_dag: /opt/airflow/dags/postgres.py
Traceback (most recent call last):
  File "/home/airflow/.local/lib/python3.7/site-packages/airflow/timetables/_cron.py", line 88, in validate
    croniter(self._expression)
  File "/home/airflow/.local/lib/python3.7/site-packages/croniter/croniter.py", line 166, in __init__
    self.expanded, self.nth_weekday_of_month = self.expand(expr_format, hash_id=hash_id)
  File "/home/airflow/.local/lib/python3.7/site-packages/croniter/croniter.py", line 778, in expand
    return cls._expand(expr_format, hash_id=hash_id)
  File "/home/airflow/.local/lib/python3.7/site-packages/croniter/croniter.py", line 744, in _expand
    expr_format))
croniter.croniter.CroniterBadCronError: [0 0 0 0 0] is not acceptable, out of range

During handling of the above exception, another exception occurred:

Traceback (most recent call last):
  File "/home/airflow/.local/lib/python3.7/site-packages/airflow/models/dagbag.py", line 437, in _process_modules
    dag.validate()
  File "/home/airflow/.local/lib/python3.7/site-packages/airflow/models/dag.py", line 668, in validate
    self.timetable.validate()
  File "/home/airflow/.local/lib/python3.7/site-packages/airflow/timetables/_cron.py", line 90, in validate
    raise AirflowTimetableInvalid(str(e))
airflow.exceptions.AirflowTimetableInvalid: [0 0 0 0 0] is not acceptable, out of range
[2023-06-05T08:45:52.791+0000] {processor.py:755} WARNING - No viable dags retrieved from /opt/airflow/dags/postgres.py
[2023-06-05T08:45:52.816+0000] {processor.py:175} INFO - Processing /opt/airflow/dags/postgres.py took 0.074 seconds
[2023-06-05T08:46:23.465+0000] {processor.py:153} INFO - Started process (PID=1037) to work on /opt/airflow/dags/postgres.py
[2023-06-05T08:46:23.468+0000] {processor.py:743} INFO - Processing file /opt/airflow/dags/postgres.py for tasks to queue
[2023-06-05T08:46:23.470+0000] {logging_mixin.py:137} INFO - [2023-06-05T08:46:23.470+0000] {dagbag.py:538} INFO - Filling up the DagBag from /opt/airflow/dags/postgres.py
[2023-06-05T08:46:23.528+0000] {logging_mixin.py:137} INFO - [2023-06-05T08:46:23.526+0000] {dagbag.py:440} ERROR - Failed to bag_dag: /opt/airflow/dags/postgres.py
Traceback (most recent call last):
  File "/home/airflow/.local/lib/python3.7/site-packages/airflow/timetables/_cron.py", line 88, in validate
    croniter(self._expression)
  File "/home/airflow/.local/lib/python3.7/site-packages/croniter/croniter.py", line 166, in __init__
    self.expanded, self.nth_weekday_of_month = self.expand(expr_format, hash_id=hash_id)
  File "/home/airflow/.local/lib/python3.7/site-packages/croniter/croniter.py", line 778, in expand
    return cls._expand(expr_format, hash_id=hash_id)
  File "/home/airflow/.local/lib/python3.7/site-packages/croniter/croniter.py", line 744, in _expand
    expr_format))
croniter.croniter.CroniterBadCronError: [0 0 0 0 0] is not acceptable, out of range

During handling of the above exception, another exception occurred:

Traceback (most recent call last):
  File "/home/airflow/.local/lib/python3.7/site-packages/airflow/models/dagbag.py", line 437, in _process_modules
    dag.validate()
  File "/home/airflow/.local/lib/python3.7/site-packages/airflow/models/dag.py", line 668, in validate
    self.timetable.validate()
  File "/home/airflow/.local/lib/python3.7/site-packages/airflow/timetables/_cron.py", line 90, in validate
    raise AirflowTimetableInvalid(str(e))
airflow.exceptions.AirflowTimetableInvalid: [0 0 0 0 0] is not acceptable, out of range
[2023-06-05T08:46:23.530+0000] {processor.py:755} WARNING - No viable dags retrieved from /opt/airflow/dags/postgres.py
[2023-06-05T08:46:23.561+0000] {processor.py:175} INFO - Processing /opt/airflow/dags/postgres.py took 0.101 seconds
[2023-06-05T08:46:54.268+0000] {processor.py:153} INFO - Started process (PID=1073) to work on /opt/airflow/dags/postgres.py
[2023-06-05T08:46:54.271+0000] {processor.py:743} INFO - Processing file /opt/airflow/dags/postgres.py for tasks to queue
[2023-06-05T08:46:54.272+0000] {logging_mixin.py:137} INFO - [2023-06-05T08:46:54.272+0000] {dagbag.py:538} INFO - Filling up the DagBag from /opt/airflow/dags/postgres.py
[2023-06-05T08:46:54.308+0000] {logging_mixin.py:137} INFO - [2023-06-05T08:46:54.306+0000] {dagbag.py:440} ERROR - Failed to bag_dag: /opt/airflow/dags/postgres.py
Traceback (most recent call last):
  File "/home/airflow/.local/lib/python3.7/site-packages/airflow/timetables/_cron.py", line 88, in validate
    croniter(self._expression)
  File "/home/airflow/.local/lib/python3.7/site-packages/croniter/croniter.py", line 166, in __init__
    self.expanded, self.nth_weekday_of_month = self.expand(expr_format, hash_id=hash_id)
  File "/home/airflow/.local/lib/python3.7/site-packages/croniter/croniter.py", line 778, in expand
    return cls._expand(expr_format, hash_id=hash_id)
  File "/home/airflow/.local/lib/python3.7/site-packages/croniter/croniter.py", line 744, in _expand
    expr_format))
croniter.croniter.CroniterBadCronError: [0 0 0 0 0] is not acceptable, out of range

During handling of the above exception, another exception occurred:

Traceback (most recent call last):
  File "/home/airflow/.local/lib/python3.7/site-packages/airflow/models/dagbag.py", line 437, in _process_modules
    dag.validate()
  File "/home/airflow/.local/lib/python3.7/site-packages/airflow/models/dag.py", line 668, in validate
    self.timetable.validate()
  File "/home/airflow/.local/lib/python3.7/site-packages/airflow/timetables/_cron.py", line 90, in validate
    raise AirflowTimetableInvalid(str(e))
airflow.exceptions.AirflowTimetableInvalid: [0 0 0 0 0] is not acceptable, out of range
[2023-06-05T08:46:54.311+0000] {processor.py:755} WARNING - No viable dags retrieved from /opt/airflow/dags/postgres.py
[2023-06-05T08:46:54.335+0000] {processor.py:175} INFO - Processing /opt/airflow/dags/postgres.py took 0.071 seconds
[2023-06-05T08:47:25.072+0000] {processor.py:153} INFO - Started process (PID=1118) to work on /opt/airflow/dags/postgres.py
[2023-06-05T08:47:25.075+0000] {processor.py:743} INFO - Processing file /opt/airflow/dags/postgres.py for tasks to queue
[2023-06-05T08:47:25.077+0000] {logging_mixin.py:137} INFO - [2023-06-05T08:47:25.077+0000] {dagbag.py:538} INFO - Filling up the DagBag from /opt/airflow/dags/postgres.py
[2023-06-05T08:47:25.126+0000] {logging_mixin.py:137} INFO - [2023-06-05T08:47:25.124+0000] {dagbag.py:440} ERROR - Failed to bag_dag: /opt/airflow/dags/postgres.py
Traceback (most recent call last):
  File "/home/airflow/.local/lib/python3.7/site-packages/airflow/timetables/_cron.py", line 88, in validate
    croniter(self._expression)
  File "/home/airflow/.local/lib/python3.7/site-packages/croniter/croniter.py", line 166, in __init__
    self.expanded, self.nth_weekday_of_month = self.expand(expr_format, hash_id=hash_id)
  File "/home/airflow/.local/lib/python3.7/site-packages/croniter/croniter.py", line 778, in expand
    return cls._expand(expr_format, hash_id=hash_id)
  File "/home/airflow/.local/lib/python3.7/site-packages/croniter/croniter.py", line 744, in _expand
    expr_format))
croniter.croniter.CroniterBadCronError: [0 0 0 0 0] is not acceptable, out of range

During handling of the above exception, another exception occurred:

Traceback (most recent call last):
  File "/home/airflow/.local/lib/python3.7/site-packages/airflow/models/dagbag.py", line 437, in _process_modules
    dag.validate()
  File "/home/airflow/.local/lib/python3.7/site-packages/airflow/models/dag.py", line 668, in validate
    self.timetable.validate()
  File "/home/airflow/.local/lib/python3.7/site-packages/airflow/timetables/_cron.py", line 90, in validate
    raise AirflowTimetableInvalid(str(e))
airflow.exceptions.AirflowTimetableInvalid: [0 0 0 0 0] is not acceptable, out of range
[2023-06-05T08:47:25.127+0000] {processor.py:755} WARNING - No viable dags retrieved from /opt/airflow/dags/postgres.py
[2023-06-05T08:47:25.164+0000] {processor.py:175} INFO - Processing /opt/airflow/dags/postgres.py took 0.099 seconds
[2023-06-05T08:47:55.912+0000] {processor.py:153} INFO - Started process (PID=1158) to work on /opt/airflow/dags/postgres.py
[2023-06-05T08:47:55.926+0000] {processor.py:743} INFO - Processing file /opt/airflow/dags/postgres.py for tasks to queue
[2023-06-05T08:47:55.929+0000] {logging_mixin.py:137} INFO - [2023-06-05T08:47:55.929+0000] {dagbag.py:538} INFO - Filling up the DagBag from /opt/airflow/dags/postgres.py
[2023-06-05T08:47:55.984+0000] {logging_mixin.py:137} INFO - [2023-06-05T08:47:55.981+0000] {dagbag.py:440} ERROR - Failed to bag_dag: /opt/airflow/dags/postgres.py
Traceback (most recent call last):
  File "/home/airflow/.local/lib/python3.7/site-packages/airflow/timetables/_cron.py", line 88, in validate
    croniter(self._expression)
  File "/home/airflow/.local/lib/python3.7/site-packages/croniter/croniter.py", line 166, in __init__
    self.expanded, self.nth_weekday_of_month = self.expand(expr_format, hash_id=hash_id)
  File "/home/airflow/.local/lib/python3.7/site-packages/croniter/croniter.py", line 778, in expand
    return cls._expand(expr_format, hash_id=hash_id)
  File "/home/airflow/.local/lib/python3.7/site-packages/croniter/croniter.py", line 744, in _expand
    expr_format))
croniter.croniter.CroniterBadCronError: [0 0 0 0 0] is not acceptable, out of range

During handling of the above exception, another exception occurred:

Traceback (most recent call last):
  File "/home/airflow/.local/lib/python3.7/site-packages/airflow/models/dagbag.py", line 437, in _process_modules
    dag.validate()
  File "/home/airflow/.local/lib/python3.7/site-packages/airflow/models/dag.py", line 668, in validate
    self.timetable.validate()
  File "/home/airflow/.local/lib/python3.7/site-packages/airflow/timetables/_cron.py", line 90, in validate
    raise AirflowTimetableInvalid(str(e))
airflow.exceptions.AirflowTimetableInvalid: [0 0 0 0 0] is not acceptable, out of range
[2023-06-05T08:47:55.988+0000] {processor.py:755} WARNING - No viable dags retrieved from /opt/airflow/dags/postgres.py
[2023-06-05T08:47:56.022+0000] {processor.py:175} INFO - Processing /opt/airflow/dags/postgres.py took 0.116 seconds
[2023-06-05T08:48:26.664+0000] {processor.py:153} INFO - Started process (PID=1193) to work on /opt/airflow/dags/postgres.py
[2023-06-05T08:48:26.667+0000] {processor.py:743} INFO - Processing file /opt/airflow/dags/postgres.py for tasks to queue
[2023-06-05T08:48:26.671+0000] {logging_mixin.py:137} INFO - [2023-06-05T08:48:26.671+0000] {dagbag.py:538} INFO - Filling up the DagBag from /opt/airflow/dags/postgres.py
[2023-06-05T08:48:26.734+0000] {logging_mixin.py:137} INFO - [2023-06-05T08:48:26.731+0000] {dagbag.py:440} ERROR - Failed to bag_dag: /opt/airflow/dags/postgres.py
Traceback (most recent call last):
  File "/home/airflow/.local/lib/python3.7/site-packages/airflow/timetables/_cron.py", line 88, in validate
    croniter(self._expression)
  File "/home/airflow/.local/lib/python3.7/site-packages/croniter/croniter.py", line 166, in __init__
    self.expanded, self.nth_weekday_of_month = self.expand(expr_format, hash_id=hash_id)
  File "/home/airflow/.local/lib/python3.7/site-packages/croniter/croniter.py", line 778, in expand
    return cls._expand(expr_format, hash_id=hash_id)
  File "/home/airflow/.local/lib/python3.7/site-packages/croniter/croniter.py", line 744, in _expand
    expr_format))
croniter.croniter.CroniterBadCronError: [0 0 0 0 0] is not acceptable, out of range

During handling of the above exception, another exception occurred:

Traceback (most recent call last):
  File "/home/airflow/.local/lib/python3.7/site-packages/airflow/models/dagbag.py", line 437, in _process_modules
    dag.validate()
  File "/home/airflow/.local/lib/python3.7/site-packages/airflow/models/dag.py", line 668, in validate
    self.timetable.validate()
  File "/home/airflow/.local/lib/python3.7/site-packages/airflow/timetables/_cron.py", line 90, in validate
    raise AirflowTimetableInvalid(str(e))
airflow.exceptions.AirflowTimetableInvalid: [0 0 0 0 0] is not acceptable, out of range
[2023-06-05T08:48:26.737+0000] {processor.py:755} WARNING - No viable dags retrieved from /opt/airflow/dags/postgres.py
[2023-06-05T08:48:26.787+0000] {processor.py:175} INFO - Processing /opt/airflow/dags/postgres.py took 0.130 seconds
[2023-06-05T08:48:57.438+0000] {processor.py:153} INFO - Started process (PID=1228) to work on /opt/airflow/dags/postgres.py
[2023-06-05T08:48:57.441+0000] {processor.py:743} INFO - Processing file /opt/airflow/dags/postgres.py for tasks to queue
[2023-06-05T08:48:57.444+0000] {logging_mixin.py:137} INFO - [2023-06-05T08:48:57.444+0000] {dagbag.py:538} INFO - Filling up the DagBag from /opt/airflow/dags/postgres.py
[2023-06-05T08:48:57.497+0000] {logging_mixin.py:137} INFO - [2023-06-05T08:48:57.495+0000] {dagbag.py:440} ERROR - Failed to bag_dag: /opt/airflow/dags/postgres.py
Traceback (most recent call last):
  File "/home/airflow/.local/lib/python3.7/site-packages/airflow/timetables/_cron.py", line 88, in validate
    croniter(self._expression)
  File "/home/airflow/.local/lib/python3.7/site-packages/croniter/croniter.py", line 166, in __init__
    self.expanded, self.nth_weekday_of_month = self.expand(expr_format, hash_id=hash_id)
  File "/home/airflow/.local/lib/python3.7/site-packages/croniter/croniter.py", line 778, in expand
    return cls._expand(expr_format, hash_id=hash_id)
  File "/home/airflow/.local/lib/python3.7/site-packages/croniter/croniter.py", line 744, in _expand
    expr_format))
croniter.croniter.CroniterBadCronError: [0 0 0 0 0] is not acceptable, out of range

During handling of the above exception, another exception occurred:

Traceback (most recent call last):
  File "/home/airflow/.local/lib/python3.7/site-packages/airflow/models/dagbag.py", line 437, in _process_modules
    dag.validate()
  File "/home/airflow/.local/lib/python3.7/site-packages/airflow/models/dag.py", line 668, in validate
    self.timetable.validate()
  File "/home/airflow/.local/lib/python3.7/site-packages/airflow/timetables/_cron.py", line 90, in validate
    raise AirflowTimetableInvalid(str(e))
airflow.exceptions.AirflowTimetableInvalid: [0 0 0 0 0] is not acceptable, out of range
[2023-06-05T08:48:57.500+0000] {processor.py:755} WARNING - No viable dags retrieved from /opt/airflow/dags/postgres.py
[2023-06-05T08:48:57.534+0000] {processor.py:175} INFO - Processing /opt/airflow/dags/postgres.py took 0.102 seconds
[2023-06-05T08:49:28.067+0000] {processor.py:153} INFO - Started process (PID=1277) to work on /opt/airflow/dags/postgres.py
[2023-06-05T08:49:28.071+0000] {processor.py:743} INFO - Processing file /opt/airflow/dags/postgres.py for tasks to queue
[2023-06-05T08:49:28.074+0000] {logging_mixin.py:137} INFO - [2023-06-05T08:49:28.074+0000] {dagbag.py:538} INFO - Filling up the DagBag from /opt/airflow/dags/postgres.py
[2023-06-05T08:49:28.127+0000] {logging_mixin.py:137} INFO - [2023-06-05T08:49:28.124+0000] {dagbag.py:440} ERROR - Failed to bag_dag: /opt/airflow/dags/postgres.py
Traceback (most recent call last):
  File "/home/airflow/.local/lib/python3.7/site-packages/airflow/timetables/_cron.py", line 88, in validate
    croniter(self._expression)
  File "/home/airflow/.local/lib/python3.7/site-packages/croniter/croniter.py", line 166, in __init__
    self.expanded, self.nth_weekday_of_month = self.expand(expr_format, hash_id=hash_id)
  File "/home/airflow/.local/lib/python3.7/site-packages/croniter/croniter.py", line 778, in expand
    return cls._expand(expr_format, hash_id=hash_id)
  File "/home/airflow/.local/lib/python3.7/site-packages/croniter/croniter.py", line 744, in _expand
    expr_format))
croniter.croniter.CroniterBadCronError: [0 0 0 0 0] is not acceptable, out of range

During handling of the above exception, another exception occurred:

Traceback (most recent call last):
  File "/home/airflow/.local/lib/python3.7/site-packages/airflow/models/dagbag.py", line 437, in _process_modules
    dag.validate()
  File "/home/airflow/.local/lib/python3.7/site-packages/airflow/models/dag.py", line 668, in validate
    self.timetable.validate()
  File "/home/airflow/.local/lib/python3.7/site-packages/airflow/timetables/_cron.py", line 90, in validate
    raise AirflowTimetableInvalid(str(e))
airflow.exceptions.AirflowTimetableInvalid: [0 0 0 0 0] is not acceptable, out of range
[2023-06-05T08:49:28.129+0000] {processor.py:755} WARNING - No viable dags retrieved from /opt/airflow/dags/postgres.py
[2023-06-05T08:49:28.165+0000] {processor.py:175} INFO - Processing /opt/airflow/dags/postgres.py took 0.104 seconds
[2023-06-05T08:49:58.657+0000] {processor.py:153} INFO - Started process (PID=1312) to work on /opt/airflow/dags/postgres.py
[2023-06-05T08:49:58.659+0000] {processor.py:743} INFO - Processing file /opt/airflow/dags/postgres.py for tasks to queue
[2023-06-05T08:49:58.661+0000] {logging_mixin.py:137} INFO - [2023-06-05T08:49:58.661+0000] {dagbag.py:538} INFO - Filling up the DagBag from /opt/airflow/dags/postgres.py
[2023-06-05T08:49:58.700+0000] {logging_mixin.py:137} INFO - [2023-06-05T08:49:58.699+0000] {dagbag.py:440} ERROR - Failed to bag_dag: /opt/airflow/dags/postgres.py
Traceback (most recent call last):
  File "/home/airflow/.local/lib/python3.7/site-packages/airflow/timetables/_cron.py", line 88, in validate
    croniter(self._expression)
  File "/home/airflow/.local/lib/python3.7/site-packages/croniter/croniter.py", line 166, in __init__
    self.expanded, self.nth_weekday_of_month = self.expand(expr_format, hash_id=hash_id)
  File "/home/airflow/.local/lib/python3.7/site-packages/croniter/croniter.py", line 778, in expand
    return cls._expand(expr_format, hash_id=hash_id)
  File "/home/airflow/.local/lib/python3.7/site-packages/croniter/croniter.py", line 744, in _expand
    expr_format))
croniter.croniter.CroniterBadCronError: [0 0 0 0 0] is not acceptable, out of range

During handling of the above exception, another exception occurred:

Traceback (most recent call last):
  File "/home/airflow/.local/lib/python3.7/site-packages/airflow/models/dagbag.py", line 437, in _process_modules
    dag.validate()
  File "/home/airflow/.local/lib/python3.7/site-packages/airflow/models/dag.py", line 668, in validate
    self.timetable.validate()
  File "/home/airflow/.local/lib/python3.7/site-packages/airflow/timetables/_cron.py", line 90, in validate
    raise AirflowTimetableInvalid(str(e))
airflow.exceptions.AirflowTimetableInvalid: [0 0 0 0 0] is not acceptable, out of range
[2023-06-05T08:49:58.703+0000] {processor.py:755} WARNING - No viable dags retrieved from /opt/airflow/dags/postgres.py
[2023-06-05T08:49:58.750+0000] {processor.py:175} INFO - Processing /opt/airflow/dags/postgres.py took 0.097 seconds
[2023-06-05T08:50:29.317+0000] {processor.py:153} INFO - Started process (PID=1361) to work on /opt/airflow/dags/postgres.py
[2023-06-05T08:50:29.320+0000] {processor.py:743} INFO - Processing file /opt/airflow/dags/postgres.py for tasks to queue
[2023-06-05T08:50:29.322+0000] {logging_mixin.py:137} INFO - [2023-06-05T08:50:29.322+0000] {dagbag.py:538} INFO - Filling up the DagBag from /opt/airflow/dags/postgres.py
[2023-06-05T08:50:29.363+0000] {logging_mixin.py:137} INFO - [2023-06-05T08:50:29.361+0000] {dagbag.py:440} ERROR - Failed to bag_dag: /opt/airflow/dags/postgres.py
Traceback (most recent call last):
  File "/home/airflow/.local/lib/python3.7/site-packages/airflow/timetables/_cron.py", line 88, in validate
    croniter(self._expression)
  File "/home/airflow/.local/lib/python3.7/site-packages/croniter/croniter.py", line 166, in __init__
    self.expanded, self.nth_weekday_of_month = self.expand(expr_format, hash_id=hash_id)
  File "/home/airflow/.local/lib/python3.7/site-packages/croniter/croniter.py", line 778, in expand
    return cls._expand(expr_format, hash_id=hash_id)
  File "/home/airflow/.local/lib/python3.7/site-packages/croniter/croniter.py", line 744, in _expand
    expr_format))
croniter.croniter.CroniterBadCronError: [0 0 0 0 0] is not acceptable, out of range

During handling of the above exception, another exception occurred:

Traceback (most recent call last):
  File "/home/airflow/.local/lib/python3.7/site-packages/airflow/models/dagbag.py", line 437, in _process_modules
    dag.validate()
  File "/home/airflow/.local/lib/python3.7/site-packages/airflow/models/dag.py", line 668, in validate
    self.timetable.validate()
  File "/home/airflow/.local/lib/python3.7/site-packages/airflow/timetables/_cron.py", line 90, in validate
    raise AirflowTimetableInvalid(str(e))
airflow.exceptions.AirflowTimetableInvalid: [0 0 0 0 0] is not acceptable, out of range
[2023-06-05T08:50:29.364+0000] {processor.py:755} WARNING - No viable dags retrieved from /opt/airflow/dags/postgres.py
[2023-06-05T08:50:29.390+0000] {processor.py:175} INFO - Processing /opt/airflow/dags/postgres.py took 0.077 seconds
[2023-06-05T08:50:59.970+0000] {processor.py:153} INFO - Started process (PID=1396) to work on /opt/airflow/dags/postgres.py
[2023-06-05T08:50:59.972+0000] {processor.py:743} INFO - Processing file /opt/airflow/dags/postgres.py for tasks to queue
[2023-06-05T08:50:59.974+0000] {logging_mixin.py:137} INFO - [2023-06-05T08:50:59.974+0000] {dagbag.py:538} INFO - Filling up the DagBag from /opt/airflow/dags/postgres.py
[2023-06-05T08:51:00.014+0000] {logging_mixin.py:137} INFO - [2023-06-05T08:51:00.011+0000] {dagbag.py:440} ERROR - Failed to bag_dag: /opt/airflow/dags/postgres.py
Traceback (most recent call last):
  File "/home/airflow/.local/lib/python3.7/site-packages/airflow/timetables/_cron.py", line 88, in validate
    croniter(self._expression)
  File "/home/airflow/.local/lib/python3.7/site-packages/croniter/croniter.py", line 166, in __init__
    self.expanded, self.nth_weekday_of_month = self.expand(expr_format, hash_id=hash_id)
  File "/home/airflow/.local/lib/python3.7/site-packages/croniter/croniter.py", line 778, in expand
    return cls._expand(expr_format, hash_id=hash_id)
  File "/home/airflow/.local/lib/python3.7/site-packages/croniter/croniter.py", line 744, in _expand
    expr_format))
croniter.croniter.CroniterBadCronError: [0 0 0 0 0] is not acceptable, out of range

During handling of the above exception, another exception occurred:

Traceback (most recent call last):
  File "/home/airflow/.local/lib/python3.7/site-packages/airflow/models/dagbag.py", line 437, in _process_modules
    dag.validate()
  File "/home/airflow/.local/lib/python3.7/site-packages/airflow/models/dag.py", line 668, in validate
    self.timetable.validate()
  File "/home/airflow/.local/lib/python3.7/site-packages/airflow/timetables/_cron.py", line 90, in validate
    raise AirflowTimetableInvalid(str(e))
airflow.exceptions.AirflowTimetableInvalid: [0 0 0 0 0] is not acceptable, out of range
[2023-06-05T08:51:00.016+0000] {processor.py:755} WARNING - No viable dags retrieved from /opt/airflow/dags/postgres.py
[2023-06-05T08:51:00.042+0000] {processor.py:175} INFO - Processing /opt/airflow/dags/postgres.py took 0.077 seconds
[2023-06-05T08:51:30.655+0000] {processor.py:153} INFO - Started process (PID=1445) to work on /opt/airflow/dags/postgres.py
[2023-06-05T08:51:30.657+0000] {processor.py:743} INFO - Processing file /opt/airflow/dags/postgres.py for tasks to queue
[2023-06-05T08:51:30.659+0000] {logging_mixin.py:137} INFO - [2023-06-05T08:51:30.659+0000] {dagbag.py:538} INFO - Filling up the DagBag from /opt/airflow/dags/postgres.py
[2023-06-05T08:51:30.700+0000] {logging_mixin.py:137} INFO - [2023-06-05T08:51:30.698+0000] {dagbag.py:440} ERROR - Failed to bag_dag: /opt/airflow/dags/postgres.py
Traceback (most recent call last):
  File "/home/airflow/.local/lib/python3.7/site-packages/airflow/timetables/_cron.py", line 88, in validate
    croniter(self._expression)
  File "/home/airflow/.local/lib/python3.7/site-packages/croniter/croniter.py", line 166, in __init__
    self.expanded, self.nth_weekday_of_month = self.expand(expr_format, hash_id=hash_id)
  File "/home/airflow/.local/lib/python3.7/site-packages/croniter/croniter.py", line 778, in expand
    return cls._expand(expr_format, hash_id=hash_id)
  File "/home/airflow/.local/lib/python3.7/site-packages/croniter/croniter.py", line 744, in _expand
    expr_format))
croniter.croniter.CroniterBadCronError: [0 0 0 0 0] is not acceptable, out of range

During handling of the above exception, another exception occurred:

Traceback (most recent call last):
  File "/home/airflow/.local/lib/python3.7/site-packages/airflow/models/dagbag.py", line 437, in _process_modules
    dag.validate()
  File "/home/airflow/.local/lib/python3.7/site-packages/airflow/models/dag.py", line 668, in validate
    self.timetable.validate()
  File "/home/airflow/.local/lib/python3.7/site-packages/airflow/timetables/_cron.py", line 90, in validate
    raise AirflowTimetableInvalid(str(e))
airflow.exceptions.AirflowTimetableInvalid: [0 0 0 0 0] is not acceptable, out of range
[2023-06-05T08:51:30.702+0000] {processor.py:755} WARNING - No viable dags retrieved from /opt/airflow/dags/postgres.py
[2023-06-05T08:51:30.730+0000] {processor.py:175} INFO - Processing /opt/airflow/dags/postgres.py took 0.080 seconds
[2023-06-05T08:52:01.310+0000] {processor.py:153} INFO - Started process (PID=1480) to work on /opt/airflow/dags/postgres.py
[2023-06-05T08:52:01.313+0000] {processor.py:743} INFO - Processing file /opt/airflow/dags/postgres.py for tasks to queue
[2023-06-05T08:52:01.315+0000] {logging_mixin.py:137} INFO - [2023-06-05T08:52:01.314+0000] {dagbag.py:538} INFO - Filling up the DagBag from /opt/airflow/dags/postgres.py
[2023-06-05T08:52:01.356+0000] {logging_mixin.py:137} INFO - [2023-06-05T08:52:01.354+0000] {dagbag.py:440} ERROR - Failed to bag_dag: /opt/airflow/dags/postgres.py
Traceback (most recent call last):
  File "/home/airflow/.local/lib/python3.7/site-packages/airflow/timetables/_cron.py", line 88, in validate
    croniter(self._expression)
  File "/home/airflow/.local/lib/python3.7/site-packages/croniter/croniter.py", line 166, in __init__
    self.expanded, self.nth_weekday_of_month = self.expand(expr_format, hash_id=hash_id)
  File "/home/airflow/.local/lib/python3.7/site-packages/croniter/croniter.py", line 778, in expand
    return cls._expand(expr_format, hash_id=hash_id)
  File "/home/airflow/.local/lib/python3.7/site-packages/croniter/croniter.py", line 744, in _expand
    expr_format))
croniter.croniter.CroniterBadCronError: [0 0 0 0 0] is not acceptable, out of range

During handling of the above exception, another exception occurred:

Traceback (most recent call last):
  File "/home/airflow/.local/lib/python3.7/site-packages/airflow/models/dagbag.py", line 437, in _process_modules
    dag.validate()
  File "/home/airflow/.local/lib/python3.7/site-packages/airflow/models/dag.py", line 668, in validate
    self.timetable.validate()
  File "/home/airflow/.local/lib/python3.7/site-packages/airflow/timetables/_cron.py", line 90, in validate
    raise AirflowTimetableInvalid(str(e))
airflow.exceptions.AirflowTimetableInvalid: [0 0 0 0 0] is not acceptable, out of range
[2023-06-05T08:52:01.358+0000] {processor.py:755} WARNING - No viable dags retrieved from /opt/airflow/dags/postgres.py
[2023-06-05T08:52:01.383+0000] {processor.py:175} INFO - Processing /opt/airflow/dags/postgres.py took 0.076 seconds
[2023-06-05T08:52:31.989+0000] {processor.py:153} INFO - Started process (PID=1530) to work on /opt/airflow/dags/postgres.py
[2023-06-05T08:52:31.991+0000] {processor.py:743} INFO - Processing file /opt/airflow/dags/postgres.py for tasks to queue
[2023-06-05T08:52:31.993+0000] {logging_mixin.py:137} INFO - [2023-06-05T08:52:31.993+0000] {dagbag.py:538} INFO - Filling up the DagBag from /opt/airflow/dags/postgres.py
[2023-06-05T08:52:32.031+0000] {logging_mixin.py:137} INFO - [2023-06-05T08:52:32.030+0000] {dagbag.py:440} ERROR - Failed to bag_dag: /opt/airflow/dags/postgres.py
Traceback (most recent call last):
  File "/home/airflow/.local/lib/python3.7/site-packages/airflow/timetables/_cron.py", line 88, in validate
    croniter(self._expression)
  File "/home/airflow/.local/lib/python3.7/site-packages/croniter/croniter.py", line 166, in __init__
    self.expanded, self.nth_weekday_of_month = self.expand(expr_format, hash_id=hash_id)
  File "/home/airflow/.local/lib/python3.7/site-packages/croniter/croniter.py", line 778, in expand
    return cls._expand(expr_format, hash_id=hash_id)
  File "/home/airflow/.local/lib/python3.7/site-packages/croniter/croniter.py", line 744, in _expand
    expr_format))
croniter.croniter.CroniterBadCronError: [0 0 0 0 0] is not acceptable, out of range

During handling of the above exception, another exception occurred:

Traceback (most recent call last):
  File "/home/airflow/.local/lib/python3.7/site-packages/airflow/models/dagbag.py", line 437, in _process_modules
    dag.validate()
  File "/home/airflow/.local/lib/python3.7/site-packages/airflow/models/dag.py", line 668, in validate
    self.timetable.validate()
  File "/home/airflow/.local/lib/python3.7/site-packages/airflow/timetables/_cron.py", line 90, in validate
    raise AirflowTimetableInvalid(str(e))
airflow.exceptions.AirflowTimetableInvalid: [0 0 0 0 0] is not acceptable, out of range
[2023-06-05T08:52:32.033+0000] {processor.py:755} WARNING - No viable dags retrieved from /opt/airflow/dags/postgres.py
[2023-06-05T08:52:32.055+0000] {processor.py:175} INFO - Processing /opt/airflow/dags/postgres.py took 0.070 seconds
[2023-06-05T08:53:02.631+0000] {processor.py:153} INFO - Started process (PID=1565) to work on /opt/airflow/dags/postgres.py
[2023-06-05T08:53:02.634+0000] {processor.py:743} INFO - Processing file /opt/airflow/dags/postgres.py for tasks to queue
[2023-06-05T08:53:02.637+0000] {logging_mixin.py:137} INFO - [2023-06-05T08:53:02.636+0000] {dagbag.py:538} INFO - Filling up the DagBag from /opt/airflow/dags/postgres.py
[2023-06-05T08:53:02.677+0000] {logging_mixin.py:137} INFO - [2023-06-05T08:53:02.675+0000] {dagbag.py:440} ERROR - Failed to bag_dag: /opt/airflow/dags/postgres.py
Traceback (most recent call last):
  File "/home/airflow/.local/lib/python3.7/site-packages/airflow/timetables/_cron.py", line 88, in validate
    croniter(self._expression)
  File "/home/airflow/.local/lib/python3.7/site-packages/croniter/croniter.py", line 166, in __init__
    self.expanded, self.nth_weekday_of_month = self.expand(expr_format, hash_id=hash_id)
  File "/home/airflow/.local/lib/python3.7/site-packages/croniter/croniter.py", line 778, in expand
    return cls._expand(expr_format, hash_id=hash_id)
  File "/home/airflow/.local/lib/python3.7/site-packages/croniter/croniter.py", line 744, in _expand
    expr_format))
croniter.croniter.CroniterBadCronError: [0 0 0 0 0] is not acceptable, out of range

During handling of the above exception, another exception occurred:

Traceback (most recent call last):
  File "/home/airflow/.local/lib/python3.7/site-packages/airflow/models/dagbag.py", line 437, in _process_modules
    dag.validate()
  File "/home/airflow/.local/lib/python3.7/site-packages/airflow/models/dag.py", line 668, in validate
    self.timetable.validate()
  File "/home/airflow/.local/lib/python3.7/site-packages/airflow/timetables/_cron.py", line 90, in validate
    raise AirflowTimetableInvalid(str(e))
airflow.exceptions.AirflowTimetableInvalid: [0 0 0 0 0] is not acceptable, out of range
[2023-06-05T08:53:02.678+0000] {processor.py:755} WARNING - No viable dags retrieved from /opt/airflow/dags/postgres.py
[2023-06-05T08:53:02.702+0000] {processor.py:175} INFO - Processing /opt/airflow/dags/postgres.py took 0.076 seconds
[2023-06-05T08:53:33.354+0000] {processor.py:153} INFO - Started process (PID=1613) to work on /opt/airflow/dags/postgres.py
[2023-06-05T08:53:33.356+0000] {processor.py:743} INFO - Processing file /opt/airflow/dags/postgres.py for tasks to queue
[2023-06-05T08:53:33.358+0000] {logging_mixin.py:137} INFO - [2023-06-05T08:53:33.358+0000] {dagbag.py:538} INFO - Filling up the DagBag from /opt/airflow/dags/postgres.py
[2023-06-05T08:53:33.402+0000] {logging_mixin.py:137} INFO - [2023-06-05T08:53:33.399+0000] {dagbag.py:440} ERROR - Failed to bag_dag: /opt/airflow/dags/postgres.py
Traceback (most recent call last):
  File "/home/airflow/.local/lib/python3.7/site-packages/airflow/timetables/_cron.py", line 88, in validate
    croniter(self._expression)
  File "/home/airflow/.local/lib/python3.7/site-packages/croniter/croniter.py", line 166, in __init__
    self.expanded, self.nth_weekday_of_month = self.expand(expr_format, hash_id=hash_id)
  File "/home/airflow/.local/lib/python3.7/site-packages/croniter/croniter.py", line 778, in expand
    return cls._expand(expr_format, hash_id=hash_id)
  File "/home/airflow/.local/lib/python3.7/site-packages/croniter/croniter.py", line 744, in _expand
    expr_format))
croniter.croniter.CroniterBadCronError: [0 0 0 0 0] is not acceptable, out of range

During handling of the above exception, another exception occurred:

Traceback (most recent call last):
  File "/home/airflow/.local/lib/python3.7/site-packages/airflow/models/dagbag.py", line 437, in _process_modules
    dag.validate()
  File "/home/airflow/.local/lib/python3.7/site-packages/airflow/models/dag.py", line 668, in validate
    self.timetable.validate()
  File "/home/airflow/.local/lib/python3.7/site-packages/airflow/timetables/_cron.py", line 90, in validate
    raise AirflowTimetableInvalid(str(e))
airflow.exceptions.AirflowTimetableInvalid: [0 0 0 0 0] is not acceptable, out of range
[2023-06-05T08:53:33.404+0000] {processor.py:755} WARNING - No viable dags retrieved from /opt/airflow/dags/postgres.py
[2023-06-05T08:53:33.432+0000] {processor.py:175} INFO - Processing /opt/airflow/dags/postgres.py took 0.083 seconds
[2023-06-05T09:03:35.224+0000] {processor.py:153} INFO - Started process (PID=1629) to work on /opt/airflow/dags/postgres.py
[2023-06-05T09:03:35.268+0000] {processor.py:743} INFO - Processing file /opt/airflow/dags/postgres.py for tasks to queue
[2023-06-05T09:03:35.283+0000] {logging_mixin.py:137} INFO - [2023-06-05T09:03:35.282+0000] {dagbag.py:538} INFO - Filling up the DagBag from /opt/airflow/dags/postgres.py
[2023-06-05T09:03:35.356+0000] {logging_mixin.py:137} INFO - [2023-06-05T09:03:35.352+0000] {dagbag.py:440} ERROR - Failed to bag_dag: /opt/airflow/dags/postgres.py
Traceback (most recent call last):
  File "/home/airflow/.local/lib/python3.7/site-packages/airflow/timetables/_cron.py", line 88, in validate
    croniter(self._expression)
  File "/home/airflow/.local/lib/python3.7/site-packages/croniter/croniter.py", line 166, in __init__
    self.expanded, self.nth_weekday_of_month = self.expand(expr_format, hash_id=hash_id)
  File "/home/airflow/.local/lib/python3.7/site-packages/croniter/croniter.py", line 778, in expand
    return cls._expand(expr_format, hash_id=hash_id)
  File "/home/airflow/.local/lib/python3.7/site-packages/croniter/croniter.py", line 744, in _expand
    expr_format))
croniter.croniter.CroniterBadCronError: [0 0 0 0 0] is not acceptable, out of range

During handling of the above exception, another exception occurred:

Traceback (most recent call last):
  File "/home/airflow/.local/lib/python3.7/site-packages/airflow/models/dagbag.py", line 437, in _process_modules
    dag.validate()
  File "/home/airflow/.local/lib/python3.7/site-packages/airflow/models/dag.py", line 668, in validate
    self.timetable.validate()
  File "/home/airflow/.local/lib/python3.7/site-packages/airflow/timetables/_cron.py", line 90, in validate
    raise AirflowTimetableInvalid(str(e))
airflow.exceptions.AirflowTimetableInvalid: [0 0 0 0 0] is not acceptable, out of range
[2023-06-05T09:03:35.358+0000] {processor.py:755} WARNING - No viable dags retrieved from /opt/airflow/dags/postgres.py
[2023-06-05T09:03:35.406+0000] {processor.py:175} INFO - Processing /opt/airflow/dags/postgres.py took 0.196 seconds
